Workbook

Sheet Dashboard
B2: DASHBOARD QPI CHECKLIST GUTTMAN 2026 — KOTA MEDAN (21 KECAMATAN)
B3: Terhubung otomatis dari sheet Cek_A..Cek_F melalui rumus — isi checklist Ya/Tidak di sheet Cek_A..Cek_F (kecamatan = kolom, indikator = baris), seluruh angka di sini menghitung ulang sendiri.
B5: RATA-RATA QPI INTI KOTA | E5: KECAMATAN KATEGORI KRITIS | G5: KECAMATAN TERKENA FLOOR | I5: KECAMATAN SANGAT BAIK | K5: KECAMATAN TERENDAH
B6: =_xlfn.IFERROR(ROUND(AVERAGE(QPI_Inti!E4:Y4),1),"") | E6: =COUNTIF(QPI_Inti!E5:Y5,"*Kritis*") -> 0 | G6: =COUNTIF(QPI_Inti!E6:Y6,"FLOOR AKTIF") -> 0 | I6: =COUNTIF(QPI_Inti!E5:Y5,"Sangat Baik") -> 0 | K6: =_xlfn.IFERROR(INDEX(QPI_Inti!E$3:Y$3,MATCH(MIN(QPI_Inti!E4:Y4),QPI_Inti!E4:Y4,0)),"-") -> -
B9: PERINGKAT 21 KECAMATAN — QPI INTI & SKOR DIMENSI D1-D7
B10: Rank | C10: Kecamatan | D10: QPI Inti | E10: Kategori | F10: D1 | G10: D2 | H10: D3 | I10: D4 | J10: D5 | K10: D6 | L10: D7 | M10: Floor
B11: =_xlfn.IFERROR(RANK(QPI_Inti!E4,QPI_Inti!E4:Y4,0),"") | C11: =QPI_Inti!E$3 -> Tembung | D11: =QPI_Inti!E4 | E11: =QPI_Inti!E5 | F11: =Skor_Dimensi!E4 | G11: =Skor_Dimensi!E5 | H11: =Skor_Dimensi!E6 | I11: =Skor_Dimensi!E7 | J11: =Skor_Dimensi!E8 | K11: =Skor_Dimensi!E9 | L11: =Skor_Dimensi!E10 | M11: =QPI_Inti!E6
B12: =_xlfn.IFERROR(RANK(QPI_Inti!F4,QPI_Inti!E4:Y4,0),"") | C12: =QPI_Inti!F$3 -> Belawan | D12: =QPI_Inti!F4 | E12: =QPI_Inti!F5 | F12: =Skor_Dimensi!F4 | G12: =Skor_Dimensi!F5 | H12: =Skor_Dimensi!F6 | I12: =Skor_Dimensi!F7 | J12: =Skor_Dimensi!F8 | K12: =Skor_Dimensi!F9 | L12: =Skor_Dimensi!F10 | M12: =QPI_Inti!F6
B13: =_xlfn.IFERROR(RANK(QPI_Inti!G4,QPI_Inti!E4:Y4,0),"") | C13: =QPI_Inti!G$3 -> Marelan | D13: =QPI_Inti!G4 | E13: =QPI_Inti!G5 | F13: =Skor_Dimensi!G4 | G13: =Skor_Dimensi!G5 | H13: =Skor_Dimensi!G6 | I13: =Skor_Dimensi!G7 | J13: =Skor_Dimensi!G8 | K13: =Skor_Dimensi!G9 | L13: =Skor_Dimensi!G10 | M13: =QPI_Inti!G6
B14: =_xlfn.IFERROR(RANK(QPI_Inti!H4,QPI_Inti!E4:Y4,0),"") | C14: =QPI_Inti!H$3 -> Amplas | D14: =QPI_Inti!H4 | E14: =QPI_Inti!H5 | F14: =Skor_Dimensi!H4 | G14: =Skor_Dimensi!H5 | H14: =Skor_Dimensi!H6 | I14: =Skor_Dimensi!H7 | J14: =Skor_Dimensi!H8 | K14: =Skor_Dimensi!H9 | L14: =Skor_Dimensi!H10 | M14: =QPI_Inti!H6
B15: =_xlfn.IFERROR(RANK(QPI_Inti!I4,QPI_Inti!E4:Y4,0),"") | C15: =QPI_Inti!I$3 -> Perjuangan | D15: =QPI_Inti!I4 | E15: =QPI_Inti!I5 | F15: =Skor_Dimensi!I4 | G15: =Skor_Dimensi!I5 | H15: =Skor_Dimensi!I6 | I15: =Skor_Dimensi!I7 | J15: =Skor_Dimensi!I8 | K15: =Skor_Dimensi!I9 | L15: =Skor_Dimensi!I10 | M15: =QPI_Inti!I6
B16: =_xlfn.IFERROR(RANK(QPI_Inti!J4,QPI_Inti!E4:Y4,0),"") | C16: =QPI_Inti!J$3 -> Deli | D16: =QPI_Inti!J4 | E16: =QPI_Inti!J5 | F16: =Skor_Dimensi!J4 | G16: =Skor_Dimensi!J5 | H16: =Skor_Dimensi!J6 | I16: =Skor_Dimensi!J7 | J16: =Skor_Dimensi!J8 | K16: =Skor_Dimensi!J9 | L16: =Skor_Dimensi!J10 | M16: =QPI_Inti!J6
B17: =_xlfn.IFERROR(RANK(QPI_Inti!K4,QPI_Inti!E4:Y4,0),"") | C17: =QPI_Inti!K$3 -> Tuntungan | D17: =QPI_Inti!K4 | E17: =QPI_Inti!K5 | F17: =Skor_Dimensi!K4 | G17: =Skor_Dimensi!K5 | H17: =Skor_Dimensi!K6 | I17: =Skor_Dimensi!K7 | J17: =Skor_Dimensi!K8 | K17: =Skor_Dimensi!K9 | L17: =Skor_Dimensi!K10 | M17: =QPI_Inti!K6
B18: =_xlfn.IFERROR(RANK(QPI_Inti!L4,QPI_Inti!E4:Y4,0),"") | C18: =QPI_Inti!L$3 -> Selayang | D18: =QPI_Inti!L4 | E18: =QPI_Inti!L5 | F18: =Skor_Dimensi!L4 | G18: =Skor_Dimensi!L5 | H18: =Skor_Dimensi!L6 | I18: =Skor_Dimensi!L7 | J18: =Skor_Dimensi!L8 | K18: =Skor_Dimensi!L9 | L18: =Skor_Dimensi!L10 | M18: =QPI_Inti!L6
B19: =_xlfn.IFERROR(RANK(QPI_Inti!M4,QPI_Inti!E4:Y4,0),"") | C19: =QPI_Inti!M$3 -> Polonia | D19: =QPI_Inti!M4 | E19: =QPI_Inti!M5 | F19: =Skor_Dimensi!M4 | G19: =Skor_Dimensi!M5 | H19: =Skor_Dimensi!M6 | I19: =Skor_Dimensi!M7 | J19: =Skor_Dimensi!M8 | K19: =Skor_Dimensi!M9 | L19: =Skor_Dimensi!M10 | M19: =QPI_Inti!M6
B20: =_xlfn.IFERROR(RANK(QPI_Inti!N4,QPI_Inti!E4:Y4,0),"") | C20: =QPI_Inti!N$3 -> Area | D20: =QPI_Inti!N4 | E20: =QPI_Inti!N5 | F20: =Skor_Dimensi!N4 | G20: =Skor_Dimensi!N5 | H20: =Skor_Dimensi!N6 | I20: =Skor_Dimensi!N7 | J20: =Skor_Dimensi!N8 | K20: =Skor_Dimensi!N9 | L20: =Skor_Dimensi!N10 | M20: =QPI_Inti!N6
B21: =_xlfn.IFERROR(RANK(QPI_Inti!O4,QPI_Inti!E4:Y4,0),"") | C21: =QPI_Inti!O$3 -> Kota | D21: =QPI_Inti!O4 | E21: =QPI_Inti!O5 | F21: =Skor_Dimensi!O4 | G21: =Skor_Dimensi!O5 | H21: =Skor_Dimensi!O6 | I21: =Skor_Dimensi!O7 | J21: =Skor_Dimensi!O8 | K21: =Skor_Dimensi!O9 | L21: =Skor_Dimensi!O10 | M21: =QPI_Inti!O6
B22: =_xlfn.IFERROR(RANK(QPI_Inti!P4,QPI_Inti!E4:Y4,0),"") | C22: =QPI_Inti!P$3 -> Baru | D22: =QPI_Inti!P4 | E22: =QPI_Inti!P5 | F22: =Skor_Dimensi!P4 | G22: =Skor_Dimensi!P5 | H22: =Skor_Dimensi!P6 | I22: =Skor_Dimensi!P7 | J22: =Skor_Dimensi!P8 | K22: =Skor_Dimensi!P9 | L22: =Skor_Dimensi!P10 | M22: =QPI_Inti!P6
B23: =_xlfn.IFERROR(RANK(QPI_Inti!Q4,QPI_Inti!E4:Y4,0),"") | C23: =QPI_Inti!Q$3 -> Johor | D23: =QPI_Inti!Q4 | E23: =QPI_Inti!Q5 | F23: =Skor_Dimensi!Q4 | G23: =Skor_Dimensi!Q5 | H23: =Skor_Dimensi!Q6 | I23: =Skor_Dimensi!Q7 | J23: =Skor_Dimensi!Q8 | K23: =Skor_Dimensi!Q9 | L23: =Skor_Dimensi!Q10 | M23: =QPI_Inti!Q6
B24: =_xlfn.IFERROR(RANK(QPI_Inti!R4,QPI_Inti!E4:Y4,0),"") | C24: =QPI_Inti!R$3 -> Denai | D24: =QPI_Inti!R4 | E24: =QPI_Inti!R5 | F24: =Skor_Dimensi!R4 | G24: =Skor_Dimensi!R5 | H24: =Skor_Dimensi!R6 | I24: =Skor_Dimensi!R7 | J24: =Skor_Dimensi!R8 | K24: =Skor_Dimensi!R9 | L24: =Skor_Dimensi!R10 | M24: =QPI_Inti!R6
B25: =_xlfn.IFERROR(RANK(QPI_Inti!S4,QPI_Inti!E4:Y4,0),"") | C25: =QPI_Inti!S$3 -> Labuhan | D25: =QPI_Inti!S4 | E25: =QPI_Inti!S5 | F25: =Skor_Dimensi!S4 | G25: =Skor_Dimensi!S5 | H25: =Skor_Dimensi!S6 | I25: =Skor_Dimensi!S7 | J25: =Skor_Dimensi!S8 | K25: =Skor_Dimensi!S9 | L25: =Skor_Dimensi!S10 | M25: =QPI_Inti!S6
B26: =_xlfn.IFERROR(RANK(QPI_Inti!T4,QPI_Inti!E4:Y4,0),"") | C26: =QPI_Inti!T$3 -> Timur | D26: =QPI_Inti!T4 | E26: =QPI_Inti!T5 | F26: =Skor_Dimensi!T4 | G26: =Skor_Dimensi!T5 | H26: =Skor_Dimensi!T6 | I26: =Skor_Dimensi!T7 | J26: =Skor_Dimensi!T8 | K26: =Skor_Dimensi!T9 | L26: =Skor_Dimensi!T10 | M26: =QPI_Inti!T6
B27: =_xlfn.IFERROR(RANK(QPI_Inti!U4,QPI_Inti!E4:Y4,0),"") | C27: =QPI_Inti!U$3 -> Barat | D27: =QPI_Inti!U4 | E27: =QPI_Inti!U5 | F27: =Skor_Dimensi!U4 | G27: =Skor_Dimensi!U5 | H27: =Skor_Dimensi!U6 | I27: =Skor_Dimensi!U7 | J27: =Skor_Dimensi!U8 | K27: =Skor_Dimensi!U9 | L27: =Skor_Dimensi!U10 | M27: =QPI_Inti!U6
B28: =_xlfn.IFERROR(RANK(QPI_Inti!V4,QPI_Inti!E4:Y4,0),"") | C28: =QPI_Inti!V$3 -> Helvetia | D28: =QPI_Inti!V4 | E28: =QPI_Inti!V5 | F28: =Skor_Dimensi!V4 | G28: =Skor_Dimensi!V5 | H28: =Skor_Dimensi!V6 | I28: =Skor_Dimensi!V7 | J28: =Skor_Dimensi!V8 | K28: =Skor_Dimensi!V9 | L28: =Skor_Dimensi!V10 | M28: =QPI_Inti!V6
B29: =_xlfn.IFERROR(RANK(QPI_Inti!W4,QPI_Inti!E4:Y4,0),"") | C29: =QPI_Inti!W$3 -> Sunggal | D29: =QPI_Inti!W4 | E29: =QPI_Inti!W5 | F29: =Skor_Dimensi!W4 | G29: =Skor_Dimensi!W5 | H29: =Skor_Dimensi!W6 | I29: =Skor_Dimensi!W7 | J29: =Skor_Dimensi!W8 | K29: =Skor_Dimensi!W9 | L29: =Skor_Dimensi!W10 | M29: =QPI_Inti!W6
B30: =_xlfn.IFERROR(RANK(QPI_Inti!X4,QPI_Inti!E4:Y4,0),"") | C30: =QPI_Inti!X$3 -> Maimun | D30: =QPI_Inti!X4 | E30: =QPI_Inti!X5 | F30: =Skor_Dimensi!X4 | G30: =Skor_Dimensi!X5 | H30: =Skor_Dimensi!X6 | I30: =Skor_Dimensi!X7 | J30: =Skor_Dimensi!X8 | K30: =Skor_Dimensi!X9 | L30: =Skor_Dimensi!X10 | M30: =QPI_Inti!X6
B31: =_xlfn.IFERROR(RANK(QPI_Inti!Y4,QPI_Inti!E4:Y4,0),"") | C31: =QPI_Inti!Y$3 -> Petisah | D31: =QPI_Inti!Y4 | E31: =QPI_Inti!Y5 | F31: =Skor_Dimensi!Y4 | G31: =Skor_Dimensi!Y5 | H31: =Skor_Dimensi!Y6 | I31: =Skor_Dimensi!Y7 | J31: =Skor_Dimensi!Y8 | K31: =Skor_Dimensi!Y9 | L31: =Skor_Dimensi!Y10 | M31: =QPI_Inti!Y6
B34: 10 SUB-ITEM KOTA YANG PALING PERLU DIBENAHI | H34: 5 SUB-VARIABEL KOTA YANG PALING PERLU DIPERHATIKAN
B35: # | C35: Kode | D35: Kuesioner | E35: Skor | H35: # | I35: Sub-Variabel | J35: Kuesioner | K35: Dimensi | L35: Skor
B36: 1 | C36: =_xlfn.IFERROR(INDEX(Master_Item!$D$3:$D$105,MATCH(SMALL(Master_Item!$G$3:$G$105,1),Master_Item!$G$3:$G$105,0)),"") | D36: =_xlfn.IFERROR(INDEX(Master_Item!$B$3:$B$105,MATCH(SMALL(Master_Item!$G$3:$G$105,1),Master_Item!$G$3:$G$105,0)),"") | E36: =_xlfn.IFERROR(ROUND(SMALL(Master_Item!$G$3:$G$105,1),1),"") | F36: =_xlfn.IFERROR(INDEX(Master_Item!$E$3:$E$105,MATCH(SMALL(Master_Item!$G$3:$G$105,1),Master_Item!$G$3:$G$105,0)),"") | H36: 1 | I36: =_xlfn.IFERROR(INDEX(Master_SubVar!$D$3:$D$30,MATCH(SMALL(Master_SubVar!$F$3:$F$30,1),Master_SubVar!$F$3:$F$30,0)),"") | J36: =_xlfn.IFERROR(INDEX(Master_SubVar!$B$3:$B$30,MATCH(SMALL(Master_SubVar!$F$3:$F$30,1),Master_SubVar!$F$3:$F$30,0)),"") | K36: =_xlfn.IFERROR(INDEX(Master_SubVar!$C$3:$C$30,MATCH(SMALL(Master_SubVar!$F$3:$F$30,1),Master_SubVar!$F$3:$F$30,0)),"") | L36: =_xlfn.IFERROR(ROUND(SMALL(Master_SubVar!$F$3:$F$30,1),1),"")
B37: 2 | C37: =_xlfn.IFERROR(INDEX(Master_Item!$D$3:$D$105,MATCH(SMALL(Master_Item!$G$3:$G$105,2),Master_Item!$G$3:$G$105,0)),"") | D37: =_xlfn.IFERROR(INDEX(Master_Item!$B$3:$B$105,MATCH(SMALL(Master_Item!$G$3:$G$105,2),Master_Item!$G$3:$G$105,0)),"") | E37: =_xlfn.IFERROR(ROUND(SMALL(Master_Item!$G$3:$G$105,2),1),"") | F37: =_xlfn.IFERROR(INDEX(Master_Item!$E$3:$E$105,MATCH(SMALL(Master_Item!$G$3:$G$105,2),Master_Item!$G$3:$G$105,0)),"") | H37: 2 | I37: =_xlfn.IFERROR(INDEX(Master_SubVar!$D$3:$D$30,MATCH(SMALL(Master_SubVar!$F$3:$F$30,2),Master_SubVar!$F$3:$F$30,0)),"") | J37: =_xlfn.IFERROR(INDEX(Master_SubVar!$B$3:$B$30,MATCH(SMALL(Master_SubVar!$F$3:$F$30,2),Master_SubVar!$F$3:$F$30,0)),"") | K37: =_xlfn.IFERROR(INDEX(Master_SubVar!$C$3:$C$30,MATCH(SMALL(Master_SubVar!$F$3:$F$30,2),Master_SubVar!$F$3:$F$30,0)),"") | L37: =_xlfn.IFERROR(ROUND(SMALL(Master_SubVar!$F$3:$F$30,2),1),"")
B38: 3 | C38: =_xlfn.IFERROR(INDEX(Master_Item!$D$3:$D$105,MATCH(SMALL(Master_Item!$G$3:$G$105,3),Master_Item!$G$3:$G$105,0)),"") | D38: =_xlfn.IFERROR(INDEX(Master_Item!$B$3:$B$105,MATCH(SMALL(Master_Item!$G$3:$G$105,3),Master_Item!$G$3:$G$105,0)),"") | E38: =_xlfn.IFERROR(ROUND(SMALL(Master_Item!$G$3:$G$105,3),1),"") | F38: =_xlfn.IFERROR(INDEX(Master_Item!$E$3:$E$105,MATCH(SMALL(Master_Item!$G$3:$G$105,3),Master_Item!$G$3:$G$105,0)),"") | H38: 3 | I38: =_xlfn.IFERROR(INDEX(Master_SubVar!$D$3:$D$30,MATCH(SMALL(Master_SubVar!$F$3:$F$30,3),Master_SubVar!$F$3:$F$30,0)),"") | J38: =_xlfn.IFERROR(INDEX(Master_SubVar!$B$3:$B$30,MATCH(SMALL(Master_SubVar!$F$3:$F$30,3),Master_SubVar!$F$3:$F$30,0)),"") | K38: =_xlfn.IFERROR(INDEX(Master_SubVar!$C$3:$C$30,MATCH(SMALL(Master_SubVar!$F$3:$F$30,3),Master_SubVar!$F$3:$F$30,0)),"") | L38: =_xlfn.IFERROR(ROUND(SMALL(Master_SubVar!$F$3:$F$30,3),1),"")
B39: 4 | C39: =_xlfn.IFERROR(INDEX(Master_Item!$D$3:$D$105,MATCH(SMALL(Master_Item!$G$3:$G$105,4),Master_Item!$G$3:$G$105,0)),"") | D39: =_xlfn.IFERROR(INDEX(Master_Item!$B$3:$B$105,MATCH(SMALL(Master_Item!$G$3:$G$105,4),Master_Item!$G$3:$G$105,0)),"") | E39: =_xlfn.IFERROR(ROUND(SMALL(Master_Item!$G$3:$G$105,4),1),"") | F39: =_xlfn.IFERROR(INDEX(Master_Item!$E$3:$E$105,MATCH(SMALL(Master_Item!$G$3:$G$105,4),Master_Item!$G$3:$G$105,0)),"") | H39: 4 | I39: =_xlfn.IFERROR(INDEX(Master_SubVar!$D$3:$D$30,MATCH(SMALL(Master_SubVar!$F$3:$F$30,4),Master_SubVar!$F$3:$F$30,0)),"") | J39: =_xlfn.IFERROR(INDEX(Master_SubVar!$B$3:$B$30,MATCH(SMALL(Master_SubVar!$F$3:$F$30,4),Master_SubVar!$F$3:$F$30,0)),"") | K39: =_xlfn.IFERROR(INDEX(Master_SubVar!$C$3:$C$30,MATCH(SMALL(Master_SubVar!$F$3:$F$30,4),Master_SubVar!$F$3:$F$30,0)),"") | L39: =_xlfn.IFERROR(ROUND(SMALL(Master_SubVar!$F$3:$F$30,4),1),"")
B40: 5 | C40: =_xlfn.IFERROR(INDEX(Master_Item!$D$3:$D$105,MATCH(SMALL(Master_Item!$G$3:$G$105,5),Master_Item!$G$3:$G$105,0)),"") | D40: =_xlfn.IFERROR(INDEX(Master_Item!$B$3:$B$105,MATCH(SMALL(Master_Item!$G$3:$G$105,5),Master_Item!$G$3:$G$105,0)),"") | E40: =_xlfn.IFERROR(ROUND(SMALL(Master_Item!$G$3:$G$105,5),1),"") | F40: =_xlfn.IFERROR(INDEX(Master_Item!$E$3:$E$105,MATCH(SMALL(Master_Item!$G$3:$G$105,5),Master_Item!$G$3:$G$105,0)),"") | H40: 5 | I40: =_xlfn.IFERROR(INDEX(Master_SubVar!$D$3:$D$30,MATCH(SMALL(Master_SubVar!$F$3:$F$30,5),Master_SubVar!$F$3:$F$30,0)),"") | J40: =_xlfn.IFERROR(INDEX(Master_SubVar!$B$3:$B$30,MATCH(SMALL(Master_SubVar!$F$3:$F$30,5),Master_SubVar!$F$3:$F$30,0)),"") | K40: =_xlfn.IFERROR(INDEX(Master_SubVar!$C$3:$C$30,MATCH(SMALL(Master_SubVar!$F$3:$F$30,5),Master_SubVar!$F$3:$F$30,0)),"") | L40: =_xlfn.IFERROR(ROUND(SMALL(Master_SubVar!$F$3:$F$30,5),1),"")
B41: 6 | C41: =_xlfn.IFERROR(INDEX(Master_Item!$D$3:$D$105,MATCH(SMALL(Master_Item!$G$3:$G$105,6),Master_Item!$G$3:$G$105,0)),"") | D41: =_xlfn.IFERROR(INDEX(Master_Item!$B$3:$B$105,MATCH(SMALL(Master_Item!$G$3:$G$105,6),Master_Item!$G$3:$G$105,0)),"") | E41: =_xlfn.IFERROR(ROUND(SMALL(Master_Item!$G$3:$G$105,6),1),"") | F41: =_xlfn.IFERROR(INDEX(Master_Item!$E$3:$E$105,MATCH(SMALL(Master_Item!$G$3:$G$105,6),Master_Item!$G$3:$G$105,0)),"")
B42: 7 | C42: =_xlfn.IFERROR(INDEX(Master_Item!$D$3:$D$105,MATCH(SMALL(Master_Item!$G$3:$G$105,7),Master_Item!$G$3:$G$105,0)),"") | D42: =_xlfn.IFERROR(INDEX(Master_Item!$B$3:$B$105,MATCH(SMALL(Master_Item!$G$3:$G$105,7),Master_Item!$G$3:$G$105,0)),"") | E42: =_xlfn.IFERROR(ROUND(SMALL(Master_Item!$G$3:$G$105,7),1),"") | F42: =_xlfn.IFERROR(INDEX(Master_Item!$E$3:$E$105,MATCH(SMALL(Master_Item!$G$3:$G$105,7),Master_Item!$G$3:$G$105,0)),"")
B43: 8 | C43: =_xlfn.IFERROR(INDEX(Master_Item!$D$3:$D$105,MATCH(SMALL(Master_Item!$G$3:$G$105,8),Master_Item!$G$3:$G$105,0)),"") | D43: =_xlfn.IFERROR(INDEX(Master_Item!$B$3:$B$105,MATCH(SMALL(Master_Item!$G$3:$G$105,8),Master_Item!$G$3:$G$105,0)),"") | E43: =_xlfn.IFERROR(ROUND(SMALL(Master_Item!$G$3:$G$105,8),1),"") | F43: =_xlfn.IFERROR(INDEX(Master_Item!$E$3:$E$105,MATCH(SMALL(Master_Item!$G$3:$G$105,8),Master_Item!$G$3:$G$105,0)),"")
B44: 9 | C44: =_xlfn.IFERROR(INDEX(Master_Item!$D$3:$D$105,MATCH(SMALL(Master_Item!$G$3:$G$105,9),Master_Item!$G$3:$G$105,0)),"") | D44: =_xlfn.IFERROR(INDEX(Master_Item!$B$3:$B$105,MATCH(SMALL(Master_Item!$G$3:$G$105,9),Master_Item!$G$3:$G$105,0)),"") | E44: =_xlfn.IFERROR(ROUND(SMALL(Master_Item!$G$3:$G$105,9),1),"") | F44: =_xlfn.IFERROR(INDEX(Master_Item!$E$3:$E$105,MATCH(SMALL(Master_Item!$G$3:$G$105,9),Master_Item!$G$3:$G$105,0)),"")
B45: 10 | C45: =_xlfn.IFERROR(INDEX(Master_Item!$D$3:$D$105,MATCH(SMALL(Master_Item!$G$3:$G$105,10),Master_Item!$G$3:$G$105,0)),"") | D45: =_xlfn.IFERROR(INDEX(Master_Item!$B$3:$B$105,MATCH(SMALL(Master_Item!$G$3:$G$105,10),Master_Item!$G$3:$G$105,0)),"") | E45: =_xlfn.IFERROR(ROUND(SMALL(Master_Item!$G$3:$G$105,10),1),"") | F45: =_xlfn.IFERROR(INDEX(Master_Item!$E$3:$E$105,MATCH(SMALL(Master_Item!$G$3:$G$105,10),Master_Item!$G$3:$G$105,0)),"")
B47: Kategori: Sangat Baik >=85 | Baik 75-<85 | Cukup 65-<75 | Perlu Perbaikan 50-<65 | Kritis <50 | Floor aktif = salah satu D1-D5 di bawah ambang floor (lihat sheet Parameter) | Warna merah->kuning->hijau = skor rendah->tinggi

Sheet Panduan
B2: PANDUAN PENGGUNAAN DASHBOARD QPI CHECKLIST GUTTMAN 2026
B4: 1. Struktur File
B5: Sheet Cek_A s.d. Cek_F : tempat pengisian data lapangan. Tiap sheet mewakili satu kuesioner (A-F). Baris = 103 indikator induk beserta 5 sub-item Guttman turunannya; kolom = 21 kecamatan Kota Medan. Kolom putih pada baris sub-item (a-e) adalah satu-satunya sel yang perlu diisi manual (dropdown Ya/Tidak).
B6: Sheet Skor_Dimensi : menghitung otomatis skor D1-D7 per kecamatan (kolom) dari hasil Cek_A..Cek_F.
B7: Sheet QPI_Inti : menghitung otomatis QPI Inti, kategori, dan status floor per kecamatan (kolom).
B8: Sheet Master_Item / Master_SubVar : rekap seluruh 103 item dan 28 sub-variabel x skor per kecamatan, dipakai Dashboard untuk mencari sub-item/sub-variabel yang paling lemah se-kota.
B9: Sheet Dashboard : ringkasan visual — KPI kota, peringkat 21 kecamatan, 10 sub-item & 5 sub-variabel yang paling perlu dibenahi.
B10: Sheet Parameter : bobot dimensi inti, ambang kategori, ambang floor, daftar kecamatan — semua dapat diedit.
B12: 2. Cara Mengisi Data
B13: Buka sheet Cek_A. Untuk setiap indikator (baris berwarna biru muda, mis. A1) terdapat 5 baris sub-item di bawahnya (A1a-A1e). Pada tiap baris sub-item, pilih 'Ya' atau 'Tidak' dari dropdown pada kolom kecamatan yang sesuai. Ulangi untuk sheet Cek_B s.d. Cek_F. Baris 'Skor' indikator (biru muda) dan baris 'SKOR SUB-VARIABEL' (kuning emas) akan otomatis terisi begitu 5 sub-item lengkap diisi.
B15: 3. Cara Membaca Hasil
B16: Begitu data di Cek_A..Cek_F terisi, buka sheet Dashboard. Kartu KPI di bagian atas menunjukkan ringkasan kota. Tabel peringkat menunjukkan QPI Inti dan D1-D7 tiap kecamatan dengan warna merah (rendah) - kuning - hijau (tinggi). Dua tabel di bawahnya menunjukkan 10 sub-item checklist dan 5 sub-variabel dengan skor rata-rata kota terendah — inilah yang paling perlu dibenahi lebih dulu.
... B33: File dashboard ini (.xlsx) — implementasi rumus tsb dalam satu workbook yang saling terhubung.

Sheet Parameter
A1: PARAMETER & PENGATURAN PERHITUNGAN
B3: Bobot Dimensi Inti QPI (D1-D5) — dapat diedit, QPI_Inti otomatis menyesuaikan
B4: D1 - Kepuasan Masyarakat (Kuesioner A) | C4: 0.26190476
B5: D2 - Tata Kelola / Good Governance (Kuesioner C) | C5: 0.14285714
B6: D3 - Proses Bisnis Internal Aparatur (Kuesioner B) | C6: 0.26190476
B7: D4 - Kematangan Digital / SPBE (Kuesioner D + B-SDM) | C7: 0.26190476
B8: D5 - Anggaran & Efisiensi Keuangan (Kuesioner B) | C8: 0.071428571
B9: Total bobot (harus = 1.0000) | C9: =SUM(C4:C8) -> 1
B11: Ambang Kategori QPI Inti & Floor Nonkompensatori
B12: Sangat Baik, jika QPI Inti >= | C12: 85
B13: Baik, jika QPI Inti >= | C13: 75
B14: Cukup, jika QPI Inti >= | C14: 65
B15: Perlu Perbaikan, jika QPI Inti >= | C15: 50
B16: Kritis, jika QPI Inti < baris di atas
B17: Ambang Floor Nonkompensatori (min. tiap dimensi D1-D5) | C17: 50 | D17: Jika salah satu dari D1-D5 < ambang floor ini, kategori kecamatan otomatis dibatasi maksimum 'Perlu Perbaikan' walaupun QPI Inti tertimbang masih tinggi (prinsip non-compensatory floor).
B19: Daftar 21 Kecamatan Kota Medan (basis urutan kolom seluruh sheet)
B20: 1 | C20: Medan Tembung
B21: 2 | C21: Medan Belawan
B22: 3 | C22: Medan Marelan
B23: 4 | C23: Medan Amplas
B24: 5 | C24: Medan Perjuangan
B25: 6 | C25: Medan Deli
B26: 7 | C26: Medan Tuntungan
B27: 8 | C27: Medan Selayang
B28: 9 | C28: Medan Polonia
B29: 10 | C29: Medan Area
B30: 11 | C30: Medan Kota
B31: 12 | C31: Medan Baru
... B40: 21 | C40: Medan Petisah
B42: Catatan Pemetaan Dimensi (lihat sheet Panduan untuk penjelasan lengkap)
B43: • D1 = seluruh Kuesioner A (Servqual Kepuasan Masyarakat)
B44: • D2 = seluruh Kuesioner C (Tata Kelola & Good Governance)
B45: • D3 = Kuesioner B, subvar Proses Bisnis Internal Persampahan + Adminduk (B1-B10)
B46: • D4 = Kuesioner D (Kematangan Digital, 10 item) digabung dengan Kuesioner B subvar SDM & Literasi Digital (B11-B13), tertimbang bobot asli masing-masing
B47: • D5 = Kuesioner B, subvar Anggaran & Efisiensi (B14-B15)
B48: • D6 = seluruh Kuesioner E (Modul Tematik PKH Makmur) — tidak masuk QPI Inti, ditampilkan terpisah
B49: • D7 = seluruh Kuesioner F (Modul Tematik Ketertiban Umum) — tidak masuk QPI Inti, ditampilkan terpisah

Sheet Cek_A
A1: CEK_A — KUESIONER A — KEPUASAN MASYARAKAT / SERVQUAL (DIMENSI D1)
A2: Skala asli instrumen: 1–5 (Ekspektasi & Persepsi). Isi kolom kecamatan (Ya/Tidak) pada baris sub-item (a-e) di bawah tiap indikator induk. Baris 'Skor' & 'SKOR SUBVAR'/'SKOR BLOK' terisi otomatis.
A3: No | B3: Kode | C3: Pernyataan / Uraian Indikator | D3: Bobot Asli (%) | E3: Tembung | F3: Belawan | G3: Marelan | H3: Amplas | I3: Perjuangan | J3: Deli | K3: Tuntungan | L3: Selayang | M3: Polonia | N3: Area | O3: Kota | P3: Baru | Q3: Johor | R3: Denai | S3: Labuhan | T3: Timur | U3: Barat | V3: Helvetia | W3: Sunggal | X3: Maimun | Y3: Petisah | Z3: Rata-rata Kota
A4: SUB-VARIABEL: A. TANGIBLES — Bukti Fisik Sarana & Fasilitas Layanan [D1]
B5: A1 | C5: Kondisi fisik kantor kecamatan/kelurahan: kebersihan, kerapian, dan kenyamanan ruang tunggu pelayanan | D5: 4 | E5: =IF(COUNTA(E6:E10)=0,"",COUNTIF(E6:E10,"Ya")/5*100) | F5: =IF(COUNTA(F6:F10)=0,"",COUNTIF(F6:F10,"Ya")/5*100) | G5: =IF(COUNTA(G6:G10)=0,"",COUNTIF(G6:G10,"Ya")/5*100) | H5: =IF(COUNTA(H6:H10)=0,"",COUNTIF(H6:H10,"Ya")/5*100) | I5: =IF(COUNTA(I6:I10)=0,"",COUNTIF(I6:I10,"Ya")/5*100) | J5: =IF(COUNTA(J6:J10)=0,"",COUNTIF(J6:J10,"Ya")/5*100) | K5: =IF(COUNTA(K6:K10)=0,"",COUNTIF(K6:K10,"Ya")/5*100) | L5: =IF(COUNTA(L6:L10)=0,"",COUNTIF(L6:L10,"Ya")/5*100) | ... Y5: =IF(COUNTA(Y6:Y10)=0,"",COUNTIF(Y6:Y10,"Ya")/5*100) | Z5: =_xlfn.IFERROR(AVERAGE(E5:Y5),"")
B6: A1a | C6: Ruang tunggu pelayanan tersedia dan dapat diakses warga tanpa hambatan
B7: A1b | C7: Ruang tunggu terlihat bersih, bebas sampah dan debu pada saat kunjungan
B8: A1c | C8: Kursi/tempat duduk tersedia dalam jumlah cukup dan tertata rapi
B9: A1d | C9: Ruang tunggu memiliki penerangan dan sirkulasi udara yang memadai (kipas angin/AC/ventilasi berfungsi)
B10: A1e | C10: Tersedia jadwal/petugas piket kebersihan ruang tunggu yang terdokumentasi dan dilaksanakan rutin
B11: A2 | C11: Ketersediaan & kelayakan TPS/Bank Sampah di kelurahan sebagai titik pengumpulan: container/bak tertutup, kapasitas memadai, tidak menimbulkan bau ke permukiman | D11: 4 | E11: =IF(COUNTA(E12:E16)=0,"",COUNTIF(E12:E16,"Ya")/5*100) | F11: =IF(COUNTA(F12:F16)=0,"",COUNTIF(F12:F16,"Ya")/5*100) | G11: =IF(COUNTA(G12:G16)=0,"",COUNTIF(G12:G16,"Ya")/5*100) | H11: =IF(COUNTA(H12:H16)=0,"",COUNTIF(H12:H16,"Ya")/5*100) | I11: =IF(COUNTA(I12:I16)=0,"",COUNTIF(I12:I16,"Ya")/5*100) | J11: =IF(COUNTA(J12:J16)=0,"",COUNTIF(J12:J16,"Ya")/5*100) | K11: =IF(COUNTA(K12:K16)=0,"",COUNTIF(K12:K16,"Ya")/5*100) | L11: =IF(COUNTA(L12:L16)=0,"",COUNTIF(L12:L16,"Ya")/5*100) | ... Y11: =IF(COUNTA(Y12:Y16)=0,"",COUNTIF(Y12:Y16,"Ya")/5*100) | Z11: =_xlfn.IFERROR(AVERAGE(E11:Y11),"")
B12: A2a | C12: TPS/Bank Sampah tersedia secara fisik di kelurahan
B13: A2b | C13: Container/bak sampah dalam kondisi tertutup, bukan terbuka atau tercecer
B14: A2c | C14: Kapasitas TPS memadai untuk menampung volume sampah harian tanpa meluap
B15: A2d | C15: Tidak tercium bau menyengat yang mengganggu permukiman di sekitar TPS saat kunjungan
B16: A2e | C16: TPS memiliki jadwal pengosongan/pembersihan rutin yang terdokumentasi dan dipatuhi
B17: A3 | C17: Kondisi & kelengkapan armada truk pengangkut sampah yang beroperasi di wilayah permukiman (layak pakai, tertutup, tidak berceceran) | D17: 4 | E17: =IF(COUNTA(E18:E22)=0,"",COUNTIF(E18:E22,"Ya")/5*100) | F17: =IF(COUNTA(F18:F22)=0,"",COUNTIF(F18:F22,"Ya")/5*100) | G17: =IF(COUNTA(G18:G22)=0,"",COUNTIF(G18:G22,"Ya")/5*100) | H17: =IF(COUNTA(H18:H22)=0,"",COUNTIF(H18:H22,"Ya")/5*100) | I17: =IF(COUNTA(I18:I22)=0,"",COUNTIF(I18:I22,"Ya")/5*100) | J17: =IF(COUNTA(J18:J22)=0,"",COUNTIF(J18:J22,"Ya")/5*100) | K17: =IF(COUNTA(K18:K22)=0,"",COUNTIF(K18:K22,"Ya")/5*100) | L17: =IF(COUNTA(L18:L22)=0,"",COUNTIF(L18:L22,"Ya")/5*100) | ... Y17: =IF(COUNTA(Y18:Y22)=0,"",COUNTIF(Y18:Y22,"Ya")/5*100) | Z17: =_xlfn.IFERROR(AVERAGE(E17:Y17),"")
B18: A3a | C18: Armada truk pengangkut sampah tersedia dan beroperasi di wilayah permukiman
B19: A3b | C19: Kondisi fisik truk layak jalan, tidak rusak berat/mogok saat beroperasi
B20: A3c | C20: Bak muatan truk tertutup terpal/penutup selama pengangkutan
B21: A3d | C21: Tidak ditemukan sampah berceceran di sepanjang rute pengangkutan
B22: A3e | C22: Armada memiliki catatan perawatan/pemeriksaan berkala yang terdokumentasi
B23: A4 | C23: Ketersediaan papan informasi jadwal pengangkutan sampah & lokasi TPS di tingkat RT/RW/kelurahan | D23: 4 | E23: =IF(COUNTA(E24:E28)=0,"",COUNTIF(E24:E28,"Ya")/5*100) | F23: =IF(COUNTA(F24:F28)=0,"",COUNTIF(F24:F28,"Ya")/5*100) | G23: =IF(COUNTA(G24:G28)=0,"",COUNTIF(G24:G28,"Ya")/5*100) | H23: =IF(COUNTA(H24:H28)=0,"",COUNTIF(H24:H28,"Ya")/5*100) | I23: =IF(COUNTA(I24:I28)=0,"",COUNTIF(I24:I28,"Ya")/5*100) | J23: =IF(COUNTA(J24:J28)=0,"",COUNTIF(J24:J28,"Ya")/5*100) | K23: =IF(COUNTA(K24:K28)=0,"",COUNTIF(K24:K28,"Ya")/5*100) | L23: =IF(COUNTA(L24:L28)=0,"",COUNTIF(L24:L28,"Ya")/5*100) | ... Y23: =IF(COUNTA(Y24:Y28)=0,"",COUNTIF(Y24:Y28,"Ya")/5*100) | Z23: =_xlfn.IFERROR(AVERAGE(E23:Y23),"")
B24: A4a | C24: Papan informasi jadwal pengangkutan sampah tersedia secara fisik di titik strategis
B25: A4b | C25: Informasi lokasi TPS tercantum jelas dan dapat dibaca warga
B26: A4c | C26: Isi informasi pada papan sesuai dengan jadwal aktual yang berlaku, tidak kedaluwarsa
B27: A4d | C27: Papan informasi terpasang di lebih dari satu titik (RT/RW/kelurahan) yang mudah dijangkau warga
B28: A4e | C28: Papan informasi diperbarui secara berkala dengan bukti tanggal pemutakhiran
B29: A5 | C29: Ketersediaan papan informasi layanan adminduk (prosedur SIBISA, jadwal jemput bola, persyaratan dokumen) di kantor kecamatan | D29: 4 | E29: =IF(COUNTA(E30:E34)=0,"",COUNTIF(E30:E34,"Ya")/5*100) | F29: =IF(COUNTA(F30:F34)=0,"",COUNTIF(F30:F34,"Ya")/5*100) | G29: =IF(COUNTA(G30:G34)=0,"",COUNTIF(G30:G34,"Ya")/5*100) | H29: =IF(COUNTA(H30:H34)=0,"",COUNTIF(H30:H34,"Ya")/5*100) | I29: =IF(COUNTA(I30:I34)=0,"",COUNTIF(I30:I34,"Ya")/5*100) | J29: =IF(COUNTA(J30:J34)=0,"",COUNTIF(J30:J34,"Ya")/5*100) | K29: =IF(COUNTA(K30:K34)=0,"",COUNTIF(K30:K34,"Ya")/5*100) | L29: =IF(COUNTA(L30:L34)=0,"",COUNTIF(L30:L34,"Ya")/5*100) | ... Y29: =IF(COUNTA(Y30:Y34)=0,"",COUNTIF(Y30:Y34,"Ya")/5*100) | Z29: =_xlfn.IFERROR(AVERAGE(E29:Y29),"")
B30: A5a | C30: Papan/media informasi layanan adminduk tersedia di kantor kecamatan
B31: A5b | C31: Prosedur permohonan SIBISA tercantum secara lengkap dan mudah dipahami
B32: A5c | C32: Persyaratan dokumen untuk tiap jenis layanan (KTP-el, KK, akta, KIA) dicantumkan rinci
B33: A5d | C33: Jadwal layanan jemput bola tercantum dan sesuai dengan pelaksanaan aktual
B34: A5e | C34: Informasi diperbarui berkala dan tersedia juga dalam bentuk digital (website/medsos/WA) yang sinkron dengan papan fisik
C35: SKOR SUB-VARIABEL: Tangibles | D35: 20 | E35: =IF((IF(ISNUMBER(E5),4,0)+IF(ISNUMBER(E11),4,0)+IF(ISNUMBER(E17),4,0)+IF(ISNUMBER(E23),4,0)+IF(ISNUMBER(E29),4,0))=0,"",(IF(ISNUMBER(E5),E5*4,0)+IF(ISNUMBER(E11),E11*4,0)+IF(ISNUMBER(E17),E17*4,0)+IF(ISNUMBER(E23),E23*4,0)+IF(ISNUMBER(E29),E29*4,0))/(IF(ISNUMBER(E5),4,0)+IF(ISNUMBER(E11),4,0)+IF(ISNUMBER(E17),4,0)+IF(ISNUMBER(E23),4,0)+IF(ISNUMBER(E29),4,0))) | F35: =IF((IF(ISNUMBER(F5),4,0)+IF(ISNUMBER(F11),4,0)+IF(ISNUMBER(F17),4,0)+IF(ISNUMBER(F23),4,0)+IF(ISNUMBER(F29),4,0))=0,"",(IF(ISNUMBER(F5),F5*4,0)+IF(ISNUMBER(F11),F11*4,0)+IF(ISNUMBER(F17),F17*4,0)+IF(ISNUMBER(F23),F23*4,0)+IF(ISNUMBER(F29),F29*4,0))/(IF(ISNUMBER(F5),4,0)+IF(ISNUMBER(F11),4,0)+IF(ISNUMBER(F17),4,0)+IF(ISNUMBER(F23),4,0)+IF(ISNUMBER(F29),4,0))) | G35: =IF((IF(ISNUMBER(G5),4,0)+IF(ISNUMBER(G11),4,0)+IF(ISNUMBER(G17),4,0)+IF(ISNUMBER(G23),4,0)+IF(ISNUMBER(G29),4,0))=0,"",(IF(ISNUMBER(G5),G5*4,0)+IF(ISNUMBER(G11),G11*4,0)+IF(ISNUMBER(G17),G17*4,0)+IF(ISNUMBER(G23),G23*4,0)+IF(ISNUMBER(G29),G29*4,0))/(IF(ISNUMBER(G5),4,0)+IF(ISNUMBER(G11),4,0)+IF(ISNUMBER(G17),4,0)+IF(ISNUMBER(G23),4,0)+IF(ISNUMBER(G29),4,0))) | H35: =IF((IF(ISNUMBER(H5),4,0)+IF(ISNUMBER(H11),4,0)+IF(ISNUMBER(H17),4,0)+IF(ISNUMBER(H23),4,0)+IF(ISNUMBER(H29),4,0))=0,"",(IF(ISNUMBER(H5),H5*4,0)+IF(ISNUMBER(H11),H11*4,0)+IF(ISNUMBER(H17),H17*4,0)+IF(ISNUMBER(H23),H23*4,0)+IF(ISNUMBER(H29),H29*4,0))/(IF(ISNUMBER(H5),4,0)+IF(ISNUMBER(H11),4,0)+IF(ISNUMBER(H17),4,0)+IF(ISNUMBER(H23),4,0)+IF(ISNUMBER(H29),4,0))) | I35: =IF((IF(ISNUMBER(I5),4,0)+IF(ISNUMBER(I11),4,0)+IF(ISNUMBER(I17),4,0)+IF(ISNUMBER(I23),4,0)+IF(ISNUMBER(I29),4,0))=0,"",(IF(ISNUMBER(I5),I5*4,0)+IF(ISNUMBER(I11),I11*4,0)+IF(ISNUMBER(I17),I17*4,0)+IF(ISNUMBER(I23),I23*4,0)+IF(ISNUMBER(I29),I29*4,0))/(IF(ISNUMBER(I5),4,0)+IF(ISNUMBER(I11),4,0)+IF(ISNUMBER(I17),4,0)+IF(ISNUMBER(I23),4,0)+IF(ISNUMBER(I29),4,0))) | J35: =IF((IF(ISNUMBER(J5),4,0)+IF(ISNUMBER(J11),4,0)+IF(ISNUMBER(J17),4,0)+IF(ISNUMBER(J23),4,0)+IF(ISNUMBER(J29),4,0))=0,"",(IF(ISNUMBER(J5),J5*4,0)+IF(ISNUMBER(J11),J11*4,0)+IF(ISNUMBER(J17),J17*4,0)+IF(ISNUMBER(J23),J23*4,0)+IF(ISNUMBER(J29),J29*4,0))/(IF(ISNUMBER(J5),4,0)+IF(ISNUMBER(J11),4,0)+IF(ISNUMBER(J17),4,0)+IF(ISNUMBER(J23),4,0)+IF(ISNUMBER(J29),4,0))) | K35: =IF((IF(ISNUMBER(K5),4,0)+IF(ISNUMBER(K11),4,0)+IF(ISNUMBER(K17),4,0)+IF(ISNUMBER(K23),4,0)+IF(ISNUMBER(K29),4,0))=0,"",(IF(ISNUMBER(K5),K5*4,0)+IF(ISNUMBER(K11),K11*4,0)+IF(ISNUMBER(K17),K17*4,0)+IF(ISNUMBER(K23),K23*4,0)+IF(ISNUMBER(K29),K29*4,0))/(IF(ISNUMBER(K5),4,0)+IF(ISNUMBER(K11),4,0)+IF(ISNUMBER(K17),4,0)+IF(ISNUMBER(K23),4,0)+IF(ISNUMBER(K29),4,0))) | L35: =IF((IF(ISNUMBER(L5),4,0)+IF(ISNUMBER(L11),4,0)+IF(ISNUMBER(L17),4,0)+IF(ISNUMBER(L23),4,0)+IF(ISNUMBER(L29),4,0))=0,"",(IF(ISNUMBER(L5),L5*4,0)+IF(ISNUMBER(L11),L11*4,0)+IF(ISNUMBER(L17),L17*4,0)+IF(ISNUMBER(L23),L23*4,0)+IF(ISNUMBER(L29),L29*4,0))/(IF(ISNUMBER(L5),4,0)+IF(ISNUMBER(L11),4,0)+IF(ISNUMBER(L17),4,0)+IF(ISNUMBER(L23),4,0)+IF(ISNUMBER(L29),4,0))) | ... Y35: =IF((IF(ISNUMBER(Y5),4,0)+IF(ISNUMBER(Y11),4,0)+IF(ISNUMBER(Y17),4,0)+IF(ISNUMBER(Y23),4,0)+IF(ISNUMBER(Y29),4,0))=0,"",(IF(ISNUMBER(Y5),Y5*4,0)+IF(ISNUMBER(Y11),Y11*4,0)+IF(ISNUMBER(Y17),Y17*4,0)+IF(ISNUMBER(Y23),Y23*4,0)+IF(ISNUMBER(Y29),Y29*4,0))/(IF(ISNUMBER(Y5),4,0)+IF(ISNUMBER(Y11),4,0)+IF(ISNUMBER(Y17),4,0)+IF(ISNUMBER(Y23),4,0)+IF(ISNUMBER(Y29),4,0))) | Z35: =_xlfn.IFERROR(AVERAGE(E35:Y35),"")
A36: SUB-VARIABEL: B. RELIABILITY — Keandalan & Konsistensi Layanan [D1]
B37: B1 | C37: Ketepatan jadwal pengangkutan sampah dari TPS/Bank Sampah menuju TPA sesuai rute dan jadwal yang ditetapkan | D37: 4 | E37: =IF(COUNTA(E38:E42)=0,"",COUNTIF(E38:E42,"Ya")/5*100) | F37: =IF(COUNTA(F38:F42)=0,"",COUNTIF(F38:F42,"Ya")/5*100) | G37: =IF(COUNTA(G38:G42)=0,"",COUNTIF(G38:G42,"Ya")/5*100) | H37: =IF(COUNTA(H38:H42)=0,"",COUNTIF(H38:H42,"Ya")/5*100) | I37: =IF(COUNTA(I38:I42)=0,"",COUNTIF(I38:I42,"Ya")/5*100) | J37: =IF(COUNTA(J38:J42)=0,"",COUNTIF(J38:J42,"Ya")/5*100) | K37: =IF(COUNTA(K38:K42)=0,"",COUNTIF(K38:K42,"Ya")/5*100) | L37: =IF(COUNTA(L38:L42)=0,"",COUNTIF(L38:L42,"Ya")/5*100) | ... Y37: =IF(COUNTA(Y38:Y42)=0,"",COUNTIF(Y38:Y42,"Ya")/5*100) | Z37: =_xlfn.IFERROR(AVERAGE(E37:Y37),"")
B38: B1a | C38: Jadwal pengangkutan sampah dari TPS ke TPA telah ditetapkan secara tertulis
B39: B1b | C39: Armada datang ke TPS sesuai hari yang dijadwalkan dalam 1 minggu terakhir
B40: B1c | C40: Armada datang sesuai rentang waktu (jam) yang dijadwalkan, bukan hanya harinya
...

Sheet Cek_B
A1: CEK_B — KUESIONER B — KINERJA INTERNAL APARATUR / BSC (DIMENSI D3, D4, D5)
A2: Skala asli instrumen: 1–5. Isi kolom kecamatan (Ya/Tidak) pada baris sub-item (a-e) di bawah tiap indikator induk. Baris 'Skor' & 'SKOR SUBVAR'/'SKOR BLOK' terisi otomatis.
A3: No | B3: Kode | C3: Pernyataan / Uraian Indikator | D3: Bobot Asli (%) | E3: Tembung | F3: Belawan | G3: Marelan | H3: Amplas | I3: Perjuangan | J3: Deli | K3: Tuntungan | L3: Selayang | M3: Polonia | N3: Area | O3: Kota | P3: Baru | Q3: Johor | R3: Denai | S3: Labuhan | T3: Timur | U3: Barat | V3: Helvetia | W3: Sunggal | X3: Maimun | Y3: Petisah | Z3: Rata-rata Kota
A4: SUB-VARIABEL: Perspektif Proses Bisnis Internal — Program Persampahan [D3]
B5: B1 | C5: Kecamatan telah menetapkan dan mengoperasikan TPS/Bank Sampah di setiap kelurahan (ada penjaga/petugas, jadwal operasional, kapasitas memadai) | D5: 7 | E5: =IF(COUNTA(E6:E10)=0,"",COUNTIF(E6:E10,"Ya")/5*100) | F5: =IF(COUNTA(F6:F10)=0,"",COUNTIF(F6:F10,"Ya")/5*100) | G5: =IF(COUNTA(G6:G10)=0,"",COUNTIF(G6:G10,"Ya")/5*100) | H5: =IF(COUNTA(H6:H10)=0,"",COUNTIF(H6:H10,"Ya")/5*100) | I5: =IF(COUNTA(I6:I10)=0,"",COUNTIF(I6:I10,"Ya")/5*100) | J5: =IF(COUNTA(J6:J10)=0,"",COUNTIF(J6:J10,"Ya")/5*100) | K5: =IF(COUNTA(K6:K10)=0,"",COUNTIF(K6:K10,"Ya")/5*100) | L5: =IF(COUNTA(L6:L10)=0,"",COUNTIF(L6:L10,"Ya")/5*100) | ... Y5: =IF(COUNTA(Y6:Y10)=0,"",COUNTIF(Y6:Y10,"Ya")/5*100) | Z5: =_xlfn.IFERROR(AVERAGE(E5:Y5),"")
B6: B1a | C6: TPS/Bank Sampah tersedia secara fisik di setiap kelurahan tanpa terkecuali
B7: B1b | C7: Setiap TPS memiliki petugas/penjaga yang ditetapkan dengan SK/penugasan resmi
B8: B1c | C8: Jadwal operasional TPS ditetapkan tertulis dan dipasang di lokasi
B9: B1d | C9: Kapasitas TPS memadai untuk volume sampah kelurahan tanpa meluap dalam kondisi normal
B10: B1e | C10: Tersedia laporan operasional TPS per kelurahan yang direkap kecamatan secara berkala
B11: B2 | C11: Kecamatan memastikan koordinasi pengangkutan dari TPS ke TPA berjalan sesuai jadwal (tidak ada akumulasi sampah > 2 hari di TPS) | D11: 7 | E11: =IF(COUNTA(E12:E16)=0,"",COUNTIF(E12:E16,"Ya")/5*100) | F11: =IF(COUNTA(F12:F16)=0,"",COUNTIF(F12:F16,"Ya")/5*100) | G11: =IF(COUNTA(G12:G16)=0,"",COUNTIF(G12:G16,"Ya")/5*100) | H11: =IF(COUNTA(H12:H16)=0,"",COUNTIF(H12:H16,"Ya")/5*100) | I11: =IF(COUNTA(I12:I16)=0,"",COUNTIF(I12:I16,"Ya")/5*100) | J11: =IF(COUNTA(J12:J16)=0,"",COUNTIF(J12:J16,"Ya")/5*100) | K11: =IF(COUNTA(K12:K16)=0,"",COUNTIF(K12:K16,"Ya")/5*100) | L11: =IF(COUNTA(L12:L16)=0,"",COUNTIF(L12:L16,"Ya")/5*100) | ... Y11: =IF(COUNTA(Y12:Y16)=0,"",COUNTIF(Y12:Y16,"Ya")/5*100) | Z11: =_xlfn.IFERROR(AVERAGE(E11:Y11),"")
B12: B2a | C12: Kecamatan memiliki mekanisme koordinasi rutin dengan pihak pengangkut sampah ke TPA
B13: B2b | C13: Jadwal pengangkutan disepakati tertulis antara kecamatan dan pihak pengangkut
B14: B2c | C14: Tidak ditemukan akumulasi sampah lebih dari 2 hari di TPS manapun pada bulan terakhir
B15: B2d | C15: Kecamatan melakukan pemantauan lapangan berkala terhadap kondisi TPS
B16: B2e | C16: Tersedia laporan koordinasi & tindak lanjut bila terjadi keterlambatan pengangkutan
B17: B3 | C17: Frekuensi penyelenggaraan operasi bersih-bersih (gotong royong) rutin di permukiman sesuai jadwal terprogram (target min. 2x/bulan) | D17: 6 | E17: =IF(COUNTA(E18:E22)=0,"",COUNTIF(E18:E22,"Ya")/5*100) | F17: =IF(COUNTA(F18:F22)=0,"",COUNTIF(F18:F22,"Ya")/5*100) | G17: =IF(COUNTA(G18:G22)=0,"",COUNTIF(G18:G22,"Ya")/5*100) | H17: =IF(COUNTA(H18:H22)=0,"",COUNTIF(H18:H22,"Ya")/5*100) | I17: =IF(COUNTA(I18:I22)=0,"",COUNTIF(I18:I22,"Ya")/5*100) | J17: =IF(COUNTA(J18:J22)=0,"",COUNTIF(J18:J22,"Ya")/5*100) | K17: =IF(COUNTA(K18:K22)=0,"",COUNTIF(K18:K22,"Ya")/5*100) | L17: =IF(COUNTA(L18:L22)=0,"",COUNTIF(L18:L22,"Ya")/5*100) | ... Y17: =IF(COUNTA(Y18:Y22)=0,"",COUNTIF(Y18:Y22,"Ya")/5*100) | Z17: =_xlfn.IFERROR(AVERAGE(E17:Y17),"")
B18: B3a | C18: Program gotong royong rutin tercantum dalam rencana kerja kecamatan/kelurahan
B19: B3b | C19: Pelaksanaan gotong royong tercatat minimal 2 kali dalam bulan terakhir
B20: B3c | C20: Frekuensi minimal 2x/bulan tersebut konsisten selama 3 bulan terakhir
B21: B3d | C21: Kegiatan melibatkan lebih dari satu kelurahan dalam wilayah kecamatan
B22: B3e | C22: Tersedia laporan/dokumentasi pelaksanaan setiap kegiatan gotong royong yang terarsip rapi
B23: B4 | C23: Tingkat optimalisasi jalur dan armada: persentase permukiman yang terlayani dari total wilayah kecamatan | D23: 7 | E23: =IF(COUNTA(E24:E28)=0,"",COUNTIF(E24:E28,"Ya")/5*100) | F23: =IF(COUNTA(F24:F28)=0,"",COUNTIF(F24:F28,"Ya")/5*100) | G23: =IF(COUNTA(G24:G28)=0,"",COUNTIF(G24:G28,"Ya")/5*100) | H23: =IF(COUNTA(H24:H28)=0,"",COUNTIF(H24:H28,"Ya")/5*100) | I23: =IF(COUNTA(I24:I28)=0,"",COUNTIF(I24:I28,"Ya")/5*100) | J23: =IF(COUNTA(J24:J28)=0,"",COUNTIF(J24:J28,"Ya")/5*100) | K23: =IF(COUNTA(K24:K28)=0,"",COUNTIF(K24:K28,"Ya")/5*100) | L23: =IF(COUNTA(L24:L28)=0,"",COUNTIF(L24:L28,"Ya")/5*100) | ... Y23: =IF(COUNTA(Y24:Y28)=0,"",COUNTIF(Y24:Y28,"Ya")/5*100) | Z23: =_xlfn.IFERROR(AVERAGE(E23:Y23),"")
B24: B4a | C24: Kecamatan memiliki data/peta wilayah permukiman yang menjadi cakupan layanan pengangkutan sampah
B25: B4b | C25: Data persentase permukiman yang terlayani telah dihitung dan didokumentasikan
B26: B4c | C26: Persentase permukiman terlayani mencapai target minimal yang ditetapkan kebijakan kota
B27: B4d | C27: Kecamatan memiliki rencana tindak lanjut untuk wilayah yang belum terlayani
B28: B4e | C28: Data cakupan layanan diperbarui secara berkala, bukan data lama/statis
B29: B5 | C29: Frekuensi kampanye edukasi tata cara buang sampah kepada warga (target min. 1x/bulan) | D29: 6 | E29: =IF(COUNTA(E30:E34)=0,"",COUNTIF(E30:E34,"Ya")/5*100) | F29: =IF(COUNTA(F30:F34)=0,"",COUNTIF(F30:F34,"Ya")/5*100) | G29: =IF(COUNTA(G30:G34)=0,"",COUNTIF(G30:G34,"Ya")/5*100) | H29: =IF(COUNTA(H30:H34)=0,"",COUNTIF(H30:H34,"Ya")/5*100) | I29: =IF(COUNTA(I30:I34)=0,"",COUNTIF(I30:I34,"Ya")/5*100) | J29: =IF(COUNTA(J30:J34)=0,"",COUNTIF(J30:J34,"Ya")/5*100) | K29: =IF(COUNTA(K30:K34)=0,"",COUNTIF(K30:K34,"Ya")/5*100) | L29: =IF(COUNTA(L30:L34)=0,"",COUNTIF(L30:L34,"Ya")/5*100) | ... Y29: =IF(COUNTA(Y30:Y34)=0,"",COUNTIF(Y30:Y34,"Ya")/5*100) | Z29: =_xlfn.IFERROR(AVERAGE(E29:Y29),"")
B30: B5a | C30: Kecamatan memiliki program kampanye edukasi persampahan yang terjadwal
B31: B5b | C31: Kampanye edukasi terlaksana minimal 1 kali pada bulan terakhir
B32: B5c | C32: Frekuensi minimal 1x/bulan tersebut konsisten selama 3 bulan terakhir
B33: B5d | C33: Kampanye menjangkau lebih dari satu segmen warga (RT/RW/sekolah/komunitas)
B34: B5e | C34: Tersedia dokumentasi/laporan hasil setiap kampanye edukasi yang dilaksanakan
C35: SKOR SUB-VARIABEL: Proses Persampahan | D35: 33 | E35: =IF((IF(ISNUMBER(E5),7,0)+IF(ISNUMBER(E11),7,0)+IF(ISNUMBER(E17),6,0)+IF(ISNUMBER(E23),7,0)+IF(ISNUMBER(E29),6,0))=0,"",(IF(ISNUMBER(E5),E5*7,0)+IF(ISNUMBER(E11),E11*7,0)+IF(ISNUMBER(E17),E17*6,0)+IF(ISNUMBER(E23),E23*7,0)+IF(ISNUMBER(E29),E29*6,0))/(IF(ISNUMBER(E5),7,0)+IF(ISNUMBER(E11),7,0)+IF(ISNUMBER(E17),6,0)+IF(ISNUMBER(E23),7,0)+IF(ISNUMBER(E29),6,0))) | F35: =IF((IF(ISNUMBER(F5),7,0)+IF(ISNUMBER(F11),7,0)+IF(ISNUMBER(F17),6,0)+IF(ISNUMBER(F23),7,0)+IF(ISNUMBER(F29),6,0))=0,"",(IF(ISNUMBER(F5),F5*7,0)+IF(ISNUMBER(F11),F11*7,0)+IF(ISNUMBER(F17),F17*6,0)+IF(ISNUMBER(F23),F23*7,0)+IF(ISNUMBER(F29),F29*6,0))/(IF(ISNUMBER(F5),7,0)+IF(ISNUMBER(F11),7,0)+IF(ISNUMBER(F17),6,0)+IF(ISNUMBER(F23),7,0)+IF(ISNUMBER(F29),6,0))) | G35: =IF((IF(ISNUMBER(G5),7,0)+IF(ISNUMBER(G11),7,0)+IF(ISNUMBER(G17),6,0)+IF(ISNUMBER(G23),7,0)+IF(ISNUMBER(G29),6,0))=0,"",(IF(ISNUMBER(G5),G5*7,0)+IF(ISNUMBER(G11),G11*7,0)+IF(ISNUMBER(G17),G17*6,0)+IF(ISNUMBER(G23),G23*7,0)+IF(ISNUMBER(G29),G29*6,0))/(IF(ISNUMBER(G5),7,0)+IF(ISNUMBER(G11),7,0)+IF(ISNUMBER(G17),6,0)+IF(ISNUMBER(G23),7,0)+IF(ISNUMBER(G29),6,0))) | H35: =IF((IF(ISNUMBER(H5),7,0)+IF(ISNUMBER(H11),7,0)+IF(ISNUMBER(H17),6,0)+IF(ISNUMBER(H23),7,0)+IF(ISNUMBER(H29),6,0))=0,"",(IF(ISNUMBER(H5),H5*7,0)+IF(ISNUMBER(H11),H11*7,0)+IF(ISNUMBER(H17),H17*6,0)+IF(ISNUMBER(H23),H23*7,0)+IF(ISNUMBER(H29),H29*6,0))/(IF(ISNUMBER(H5),7,0)+IF(ISNUMBER(H11),7,0)+IF(ISNUMBER(H17),6,0)+IF(ISNUMBER(H23),7,0)+IF(ISNUMBER(H29),6,0))) | I35: =IF((IF(ISNUMBER(I5),7,0)+IF(ISNUMBER(I11),7,0)+IF(ISNUMBER(I17),6,0)+IF(ISNUMBER(I23),7,0)+IF(ISNUMBER(I29),6,0))=0,"",(IF(ISNUMBER(I5),I5*7,0)+IF(ISNUMBER(I11),I11*7,0)+IF(ISNUMBER(I17),I17*6,0)+IF(ISNUMBER(I23),I23*7,0)+IF(ISNUMBER(I29),I29*6,0))/(IF(ISNUMBER(I5),7,0)+IF(ISNUMBER(I11),7,0)+IF(ISNUMBER(I17),6,0)+IF(ISNUMBER(I23),7,0)+IF(ISNUMBER(I29),6,0))) | J35: =IF((IF(ISNUMBER(J5),7,0)+IF(ISNUMBER(J11),7,0)+IF(ISNUMBER(J17),6,0)+IF(ISNUMBER(J23),7,0)+IF(ISNUMBER(J29),6,0))=0,"",(IF(ISNUMBER(J5),J5*7,0)+IF(ISNUMBER(J11),J11*7,0)+IF(ISNUMBER(J17),J17*6,0)+IF(ISNUMBER(J23),J23*7,0)+IF(ISNUMBER(J29),J29*6,0))/(IF(ISNUMBER(J5),7,0)+IF(ISNUMBER(J11),7,0)+IF(ISNUMBER(J17),6,0)+IF(ISNUMBER(J23),7,0)+IF(ISNUMBER(J29),6,0))) | K35: =IF((IF(ISNUMBER(K5),7,0)+IF(ISNUMBER(K11),7,0)+IF(ISNUMBER(K17),6,0)+IF(ISNUMBER(K23),7,0)+IF(ISNUMBER(K29),6,0))=0,"",(IF(ISNUMBER(K5),K5*7,0)+IF(ISNUMBER(K11),K11*7,0)+IF(ISNUMBER(K17),K17*6,0)+IF(ISNUMBER(K23),K23*7,0)+IF(ISNUMBER(K29),K29*6,0))/(IF(ISNUMBER(K5),7,0)+IF(ISNUMBER(K11),7,0)+IF(ISNUMBER(K17),6,0)+IF(ISNUMBER(K23),7,0)+IF(ISNUMBER(K29),6,0))) | L35: =IF((IF(ISNUMBER(L5),7,0)+IF(ISNUMBER(L11),7,0)+IF(ISNUMBER(L17),6,0)+IF(ISNUMBER(L23),7,0)+IF(ISNUMBER(L29),6,0))=0,"",(IF(ISNUMBER(L5),L5*7,0)+IF(ISNUMBER(L11),L11*7,0)+IF(ISNUMBER(L17),L17*6,0)+IF(ISNUMBER(L23),L23*7,0)+IF(ISNUMBER(L29),L29*6,0))/(IF(ISNUMBER(L5),7,0)+IF(ISNUMBER(L11),7,0)+IF(ISNUMBER(L17),6,0)+IF(ISNUMBER(L23),7,0)+IF(ISNUMBER(L29),6,0))) | ... Y35: =IF((IF(ISNUMBER(Y5),7,0)+IF(ISNUMBER(Y11),7,0)+IF(ISNUMBER(Y17),6,0)+IF(ISNUMBER(Y23),7,0)+IF(ISNUMBER(Y29),6,0))=0,"",(IF(ISNUMBER(Y5),Y5*7,0)+IF(ISNUMBER(Y11),Y11*7,0)+IF(ISNUMBER(Y17),Y17*6,0)+IF(ISNUMBER(Y23),Y23*7,0)+IF(ISNUMBER(Y29),Y29*6,0))/(IF(ISNUMBER(Y5),7,0)+IF(ISNUMBER(Y11),7,0)+IF(ISNUMBER(Y17),6,0)+IF(ISNUMBER(Y23),7,0)+IF(ISNUMBER(Y29),6,0))) | Z35: =_xlfn.IFERROR(AVERAGE(E35:Y35),"")
A36: SUB-VARIABEL: Perspektif Proses Bisnis Internal — Program Adminduk [D3]
B37: B6 | C37: Kecamatan aktif mempromosikan & membimbing warga menggunakan SIBISA untuk permohonan dokumen dari rumah | D37: 6 | E37: =IF(COUNTA(E38:E42)=0,"",COUNTIF(E38:E42,"Ya")/5*100) | F37: =IF(COUNTA(F38:F42)=0,"",COUNTIF(F38:F42,"Ya")/5*100) | G37: =IF(COUNTA(G38:G42)=0,"",COUNTIF(G38:G42,"Ya")/5*100) | H37: =IF(COUNTA(H38:H42)=0,"",COUNTIF(H38:H42,"Ya")/5*100) | I37: =IF(COUNTA(I38:I42)=0,"",COUNTIF(I38:I42,"Ya")/5*100) | J37: =IF(COUNTA(J38:J42)=0,"",COUNTIF(J38:J42,"Ya")/5*100) | K37: =IF(COUNTA(K38:K42)=0,"",COUNTIF(K38:K42,"Ya")/5*100) | L37: =IF(COUNTA(L38:L42)=0,"",COUNTIF(L38:L42,"Ya")/5*100) | ... Y37: =IF(COUNTA(Y38:Y42)=0,"",COUNTIF(Y38:Y42,"Ya")/5*100) | Z37: =_xlfn.IFERROR(AVERAGE(E37:Y37),"")
B38: B6a | C38: Kecamatan memiliki materi promosi (banner/pamflet/konten) tentang penggunaan SIBISA
B39: B6b | C39: Aparatur pernah memberikan bimbingan langsung/pelatihan singkat kepada warga tentang SIBISA
B40: B6c | C40: Promosi SIBISA dilakukan melalui lebih dari satu kanal (tatap muka, medsos, RT/RW)
...

Sheet Cek_C
A1: CEK_C — KUESIONER C — TATA KELOLA & GOOD GOVERNANCE (DIMENSI D2)
A2: Skala asli instrumen: 1–5. Isi kolom kecamatan (Ya/Tidak) pada baris sub-item (a-e) di bawah tiap indikator induk. Baris 'Skor' & 'SKOR SUBVAR'/'SKOR BLOK' terisi otomatis.
A3: No | B3: Kode | C3: Pernyataan / Uraian Indikator | D3: Bobot Asli (%) | E3: Tembung | F3: Belawan | G3: Marelan | H3: Amplas | I3: Perjuangan | J3: Deli | K3: Tuntungan | L3: Selayang | M3: Polonia | N3: Area | O3: Kota | P3: Baru | Q3: Johor | R3: Denai | S3: Labuhan | T3: Timur | U3: Barat | V3: Helvetia | W3: Sunggal | X3: Maimun | Y3: Petisah | Z3: Rata-rata Kota
A4: SUB-VARIABEL: Transparansi — Keterbukaan Informasi Program Persampahan & Adminduk [D2]
B5: C1 | C5: Jadwal pengangkutan sampah dari TPS ke TPA diumumkan secara terbuka kepada warga (papan pengumuman, grup WA RT/RW, medsos kelurahan) | D5: 6.25 | E5: =IF(COUNTA(E6:E10)=0,"",COUNTIF(E6:E10,"Ya")/5*100) | F5: =IF(COUNTA(F6:F10)=0,"",COUNTIF(F6:F10,"Ya")/5*100) | G5: =IF(COUNTA(G6:G10)=0,"",COUNTIF(G6:G10,"Ya")/5*100) | H5: =IF(COUNTA(H6:H10)=0,"",COUNTIF(H6:H10,"Ya")/5*100) | I5: =IF(COUNTA(I6:I10)=0,"",COUNTIF(I6:I10,"Ya")/5*100) | J5: =IF(COUNTA(J6:J10)=0,"",COUNTIF(J6:J10,"Ya")/5*100) | K5: =IF(COUNTA(K6:K10)=0,"",COUNTIF(K6:K10,"Ya")/5*100) | L5: =IF(COUNTA(L6:L10)=0,"",COUNTIF(L6:L10,"Ya")/5*100) | ... Y5: =IF(COUNTA(Y6:Y10)=0,"",COUNTIF(Y6:Y10,"Ya")/5*100) | Z5: =_xlfn.IFERROR(AVERAGE(E5:Y5),"")
B6: C1a | C6: Jadwal pengangkutan sampah tersedia dalam bentuk tertulis/dokumen resmi
B7: C1b | C7: Jadwal tersebut dipasang di papan pengumuman fisik yang dapat dilihat warga
B8: C1c | C8: Jadwal juga disebarkan melalui grup WA RT/RW atau media sosial kelurahan
B9: C1d | C9: Informasi yang diumumkan sesuai dengan pelaksanaan aktual, tidak menyesatkan
B10: C1e | C10: Pembaruan jadwal, bila ada perubahan, diumumkan ulang melalui kanal yang sama
B11: C2 | C11: Informasi lokasi, kapasitas, jam operasional & tata tertib TPS/Bank Sampah tersedia dan mudah diakses warga | D11: 6.25 | E11: =IF(COUNTA(E12:E16)=0,"",COUNTIF(E12:E16,"Ya")/5*100) | F11: =IF(COUNTA(F12:F16)=0,"",COUNTIF(F12:F16,"Ya")/5*100) | G11: =IF(COUNTA(G12:G16)=0,"",COUNTIF(G12:G16,"Ya")/5*100) | H11: =IF(COUNTA(H12:H16)=0,"",COUNTIF(H12:H16,"Ya")/5*100) | I11: =IF(COUNTA(I12:I16)=0,"",COUNTIF(I12:I16,"Ya")/5*100) | J11: =IF(COUNTA(J12:J16)=0,"",COUNTIF(J12:J16,"Ya")/5*100) | K11: =IF(COUNTA(K12:K16)=0,"",COUNTIF(K12:K16,"Ya")/5*100) | L11: =IF(COUNTA(L12:L16)=0,"",COUNTIF(L12:L16,"Ya")/5*100) | ... Y11: =IF(COUNTA(Y12:Y16)=0,"",COUNTIF(Y12:Y16,"Ya")/5*100) | Z11: =_xlfn.IFERROR(AVERAGE(E11:Y11),"")
B12: C2a | C12: Informasi lokasi TPS/Bank Sampah dapat diperoleh warga dengan mudah
B13: C2b | C13: Informasi kapasitas & jam operasional TPS dipublikasikan
B14: C2c | C14: Tata tertib penggunaan TPS (jenis sampah, jam buang) dipasang di lokasi
B15: C2d | C15: Informasi tersedia dalam lebih dari satu bentuk, baik papan fisik maupun digital
B16: C2e | C16: Informasi diperbarui bila terjadi perubahan kebijakan/operasional TPS
B17: C3 | C17: Prosedur, persyaratan & biaya layanan SIBISA dipublikasikan jelas di website, papan pengumuman, dan/atau media sosial kecamatan | D17: 6.25 | E17: =IF(COUNTA(E18:E22)=0,"",COUNTIF(E18:E22,"Ya")/5*100) | F17: =IF(COUNTA(F18:F22)=0,"",COUNTIF(F18:F22,"Ya")/5*100) | G17: =IF(COUNTA(G18:G22)=0,"",COUNTIF(G18:G22,"Ya")/5*100) | H17: =IF(COUNTA(H18:H22)=0,"",COUNTIF(H18:H22,"Ya")/5*100) | I17: =IF(COUNTA(I18:I22)=0,"",COUNTIF(I18:I22,"Ya")/5*100) | J17: =IF(COUNTA(J18:J22)=0,"",COUNTIF(J18:J22,"Ya")/5*100) | K17: =IF(COUNTA(K18:K22)=0,"",COUNTIF(K18:K22,"Ya")/5*100) | L17: =IF(COUNTA(L18:L22)=0,"",COUNTIF(L18:L22,"Ya")/5*100) | ... Y17: =IF(COUNTA(Y18:Y22)=0,"",COUNTIF(Y18:Y22,"Ya")/5*100) | Z17: =_xlfn.IFERROR(AVERAGE(E17:Y17),"")
B18: C3a | C18: Prosedur pengajuan SIBISA dipublikasikan secara tertulis
B19: C3b | C19: Persyaratan dokumen untuk tiap jenis layanan dicantumkan lengkap
B20: C3c | C20: Informasi biaya, termasuk pernyataan gratis bila berlaku, dinyatakan eksplisit
B21: C3d | C21: Publikasi tersedia di lebih dari satu kanal (website/papan/medsos kecamatan)
B22: C3e | C22: Informasi tersebut sesuai dengan praktik pelayanan aktual saat diverifikasi, tidak ada pungutan tidak resmi
B23: C4 | C23: Jadwal layanan jemput bola adminduk diumumkan jauh hari sebelum pelaksanaan (kelurahan dikunjungi, tanggal, waktu, jenis dokumen) | D23: 6.25 | E23: =IF(COUNTA(E24:E28)=0,"",COUNTIF(E24:E28,"Ya")/5*100) | F23: =IF(COUNTA(F24:F28)=0,"",COUNTIF(F24:F28,"Ya")/5*100) | G23: =IF(COUNTA(G24:G28)=0,"",COUNTIF(G24:G28,"Ya")/5*100) | H23: =IF(COUNTA(H24:H28)=0,"",COUNTIF(H24:H28,"Ya")/5*100) | I23: =IF(COUNTA(I24:I28)=0,"",COUNTIF(I24:I28,"Ya")/5*100) | J23: =IF(COUNTA(J24:J28)=0,"",COUNTIF(J24:J28,"Ya")/5*100) | K23: =IF(COUNTA(K24:K28)=0,"",COUNTIF(K24:K28,"Ya")/5*100) | L23: =IF(COUNTA(L24:L28)=0,"",COUNTIF(L24:L28,"Ya")/5*100) | ... Y23: =IF(COUNTA(Y24:Y28)=0,"",COUNTIF(Y24:Y28,"Ya")/5*100) | Z23: =_xlfn.IFERROR(AVERAGE(E23:Y23),"")
B24: C4a | C24: Jadwal jemput bola diumumkan minimal 3 hari sebelum pelaksanaan
B25: C4b | C25: Pengumuman mencantumkan kelurahan, tanggal, waktu, dan jenis dokumen yang dilayani
B26: C4c | C26: Pengumuman disebarkan melalui kanal yang menjangkau warga kelurahan sasaran (RT/RW/WA/papan)
B27: C4d | C27: Realisasi pelaksanaan sesuai dengan yang diumumkan, tidak berubah mendadak tanpa notifikasi
B28: C4e | C28: Tersedia bukti/arsip pengumuman untuk setiap sesi jemput bola yang dilaksanakan
C29: SKOR SUB-VARIABEL: Transparansi | D29: 25 | E29: =IF((IF(ISNUMBER(E5),6.25,0)+IF(ISNUMBER(E11),6.25,0)+IF(ISNUMBER(E17),6.25,0)+IF(ISNUMBER(E23),6.25,0))=0,"",(IF(ISNUMBER(E5),E5*6.25,0)+IF(ISNUMBER(E11),E11*6.25,0)+IF(ISNUMBER(E17),E17*6.25,0)+IF(ISNUMBER(E23),E23*6.25,0))/(IF(ISNUMBER(E5),6.25,0)+IF(ISNUMBER(E11),6.25,0)+IF(ISNUMBER(E17),6.25,0)+IF(ISNUMBER(E23),6.25,0))) | F29: =IF((IF(ISNUMBER(F5),6.25,0)+IF(ISNUMBER(F11),6.25,0)+IF(ISNUMBER(F17),6.25,0)+IF(ISNUMBER(F23),6.25,0))=0,"",(IF(ISNUMBER(F5),F5*6.25,0)+IF(ISNUMBER(F11),F11*6.25,0)+IF(ISNUMBER(F17),F17*6.25,0)+IF(ISNUMBER(F23),F23*6.25,0))/(IF(ISNUMBER(F5),6.25,0)+IF(ISNUMBER(F11),6.25,0)+IF(ISNUMBER(F17),6.25,0)+IF(ISNUMBER(F23),6.25,0))) | G29: =IF((IF(ISNUMBER(G5),6.25,0)+IF(ISNUMBER(G11),6.25,0)+IF(ISNUMBER(G17),6.25,0)+IF(ISNUMBER(G23),6.25,0))=0,"",(IF(ISNUMBER(G5),G5*6.25,0)+IF(ISNUMBER(G11),G11*6.25,0)+IF(ISNUMBER(G17),G17*6.25,0)+IF(ISNUMBER(G23),G23*6.25,0))/(IF(ISNUMBER(G5),6.25,0)+IF(ISNUMBER(G11),6.25,0)+IF(ISNUMBER(G17),6.25,0)+IF(ISNUMBER(G23),6.25,0))) | H29: =IF((IF(ISNUMBER(H5),6.25,0)+IF(ISNUMBER(H11),6.25,0)+IF(ISNUMBER(H17),6.25,0)+IF(ISNUMBER(H23),6.25,0))=0,"",(IF(ISNUMBER(H5),H5*6.25,0)+IF(ISNUMBER(H11),H11*6.25,0)+IF(ISNUMBER(H17),H17*6.25,0)+IF(ISNUMBER(H23),H23*6.25,0))/(IF(ISNUMBER(H5),6.25,0)+IF(ISNUMBER(H11),6.25,0)+IF(ISNUMBER(H17),6.25,0)+IF(ISNUMBER(H23),6.25,0))) | I29: =IF((IF(ISNUMBER(I5),6.25,0)+IF(ISNUMBER(I11),6.25,0)+IF(ISNUMBER(I17),6.25,0)+IF(ISNUMBER(I23),6.25,0))=0,"",(IF(ISNUMBER(I5),I5*6.25,0)+IF(ISNUMBER(I11),I11*6.25,0)+IF(ISNUMBER(I17),I17*6.25,0)+IF(ISNUMBER(I23),I23*6.25,0))/(IF(ISNUMBER(I5),6.25,0)+IF(ISNUMBER(I11),6.25,0)+IF(ISNUMBER(I17),6.25,0)+IF(ISNUMBER(I23),6.25,0))) | J29: =IF((IF(ISNUMBER(J5),6.25,0)+IF(ISNUMBER(J11),6.25,0)+IF(ISNUMBER(J17),6.25,0)+IF(ISNUMBER(J23),6.25,0))=0,"",(IF(ISNUMBER(J5),J5*6.25,0)+IF(ISNUMBER(J11),J11*6.25,0)+IF(ISNUMBER(J17),J17*6.25,0)+IF(ISNUMBER(J23),J23*6.25,0))/(IF(ISNUMBER(J5),6.25,0)+IF(ISNUMBER(J11),6.25,0)+IF(ISNUMBER(J17),6.25,0)+IF(ISNUMBER(J23),6.25,0))) | K29: =IF((IF(ISNUMBER(K5),6.25,0)+IF(ISNUMBER(K11),6.25,0)+IF(ISNUMBER(K17),6.25,0)+IF(ISNUMBER(K23),6.25,0))=0,"",(IF(ISNUMBER(K5),K5*6.25,0)+IF(ISNUMBER(K11),K11*6.25,0)+IF(ISNUMBER(K17),K17*6.25,0)+IF(ISNUMBER(K23),K23*6.25,0))/(IF(ISNUMBER(K5),6.25,0)+IF(ISNUMBER(K11),6.25,0)+IF(ISNUMBER(K17),6.25,0)+IF(ISNUMBER(K23),6.25,0))) | L29: =IF((IF(ISNUMBER(L5),6.25,0)+IF(ISNUMBER(L11),6.25,0)+IF(ISNUMBER(L17),6.25,0)+IF(ISNUMBER(L23),6.25,0))=0,"",(IF(ISNUMBER(L5),L5*6.25,0)+IF(ISNUMBER(L11),L11*6.25,0)+IF(ISNUMBER(L17),L17*6.25,0)+IF(ISNUMBER(L23),L23*6.25,0))/(IF(ISNUMBER(L5),6.25,0)+IF(ISNUMBER(L11),6.25,0)+IF(ISNUMBER(L17),6.25,0)+IF(ISNUMBER(L23),6.25,0))) | ... Y29: =IF((IF(ISNUMBER(Y5),6.25,0)+IF(ISNUMBER(Y11),6.25,0)+IF(ISNUMBER(Y17),6.25,0)+IF(ISNUMBER(Y23),6.25,0))=0,"",(IF(ISNUMBER(Y5),Y5*6.25,0)+IF(ISNUMBER(Y11),Y11*6.25,0)+IF(ISNUMBER(Y17),Y17*6.25,0)+IF(ISNUMBER(Y23),Y23*6.25,0))/(IF(ISNUMBER(Y5),6.25,0)+IF(ISNUMBER(Y11),6.25,0)+IF(ISNUMBER(Y17),6.25,0)+IF(ISNUMBER(Y23),6.25,0))) | Z29: =_xlfn.IFERROR(AVERAGE(E29:Y29),"")
A30: SUB-VARIABEL: Akuntabilitas — Pertanggungjawaban & Mekanisme Pengaduan [D2]
B31: C5 | C31: Kecamatan memiliki laporan evaluasi berkala kondisi & operasional TPS serta capaian program pengangkutan yang dapat diakses publik | D31: 6.25 | E31: =IF(COUNTA(E32:E36)=0,"",COUNTIF(E32:E36,"Ya")/5*100) | F31: =IF(COUNTA(F32:F36)=0,"",COUNTIF(F32:F36,"Ya")/5*100) | G31: =IF(COUNTA(G32:G36)=0,"",COUNTIF(G32:G36,"Ya")/5*100) | H31: =IF(COUNTA(H32:H36)=0,"",COUNTIF(H32:H36,"Ya")/5*100) | I31: =IF(COUNTA(I32:I36)=0,"",COUNTIF(I32:I36,"Ya")/5*100) | J31: =IF(COUNTA(J32:J36)=0,"",COUNTIF(J32:J36,"Ya")/5*100) | K31: =IF(COUNTA(K32:K36)=0,"",COUNTIF(K32:K36,"Ya")/5*100) | L31: =IF(COUNTA(L32:L36)=0,"",COUNTIF(L32:L36,"Ya")/5*100) | ... Y31: =IF(COUNTA(Y32:Y36)=0,"",COUNTIF(Y32:Y36,"Ya")/5*100) | Z31: =_xlfn.IFERROR(AVERAGE(E31:Y31),"")
B32: C5a | C32: Kecamatan menyusun laporan evaluasi TPS secara berkala (bulanan/triwulanan)
B33: C5b | C33: Laporan mencakup data kondisi fisik dan operasional tiap TPS
B34: C5c | C34: Laporan mencakup capaian program pengangkutan: volume, frekuensi, dan kendala
B35: C5d | C35: Laporan tersebut dapat diakses/diminta oleh publik atau warga yang berkepentingan
B36: C5e | C36: Laporan digunakan sebagai dasar tindak lanjut/perbaikan yang terdokumentasi
B37: C6 | C37: Tersedia mekanisme pengaduan yang jelas bagi warga untuk melaporkan TPS meluap, armada tidak datang, atau gangguan lingkungan — serta ditindaklanjuti nyata | D37: 6.25 | E37: =IF(COUNTA(E38:E42)=0,"",COUNTIF(E38:E42,"Ya")/5*100) | F37: =IF(COUNTA(F38:F42)=0,"",COUNTIF(F38:F42,"Ya")/5*100) | G37: =IF(COUNTA(G38:G42)=0,"",COUNTIF(G38:G42,"Ya")/5*100) | H37: =IF(COUNTA(H38:H42)=0,"",COUNTIF(H38:H42,"Ya")/5*100) | I37: =IF(COUNTA(I38:I42)=0,"",COUNTIF(I38:I42,"Ya")/5*100) | J37: =IF(COUNTA(J38:J42)=0,"",COUNTIF(J38:J42,"Ya")/5*100) | K37: =IF(COUNTA(K38:K42)=0,"",COUNTIF(K38:K42,"Ya")/5*100) | L37: =IF(COUNTA(L38:L42)=0,"",COUNTIF(L38:L42,"Ya")/5*100) | ... Y37: =IF(COUNTA(Y38:Y42)=0,"",COUNTIF(Y38:Y42,"Ya")/5*100) | Z37: =_xlfn.IFERROR(AVERAGE(E37:Y37),"")
B38: C6a | C38: Kanal pengaduan resmi terkait TPS meluap/armada tidak datang tersedia dan diketahui warga
B39: C6b | C39: Prosedur pengaduan (cara melapor, ke siapa) diinformasikan secara terbuka
B40: C6c | C40: Pengaduan yang masuk dicatat dalam suatu sistem/buku register
...

Sheet Cek_D
A1: CEK_D — KUESIONER D — KEMATANGAN DIGITAL / SPBE (DIMENSI D4)
A2: Skala asli instrumen: 1–4 (Maturity). Isi kolom kecamatan (Ya/Tidak) pada baris sub-item (a-e) di bawah tiap indikator induk. Baris 'Skor' & 'SKOR SUBVAR'/'SKOR BLOK' terisi otomatis.
A3: No | B3: Kode | C3: Pernyataan / Uraian Indikator | D3: Bobot Asli (%) | E3: Tembung | F3: Belawan | G3: Marelan | H3: Amplas | I3: Perjuangan | J3: Deli | K3: Tuntungan | L3: Selayang | M3: Polonia | N3: Area | O3: Kota | P3: Baru | Q3: Johor | R3: Denai | S3: Labuhan | T3: Timur | U3: Barat | V3: Helvetia | W3: Sunggal | X3: Maimun | Y3: Petisah | Z3: Rata-rata Kota
A4: SUB-VARIABEL: Layanan Digital Adminduk — SIBISA & Integrasi Data [D4]
B5: D1 | C5: Kecamatan menggunakan SIBISA secara aktif untuk SEMUA layanan adminduk (KTP-el, KK, Akta Kelahiran, KIA) — bukan hanya sebagian | D5: 10 | E5: =IF(COUNTA(E6:E10)=0,"",COUNTIF(E6:E10,"Ya")/5*100) | F5: =IF(COUNTA(F6:F10)=0,"",COUNTIF(F6:F10,"Ya")/5*100) | G5: =IF(COUNTA(G6:G10)=0,"",COUNTIF(G6:G10,"Ya")/5*100) | H5: =IF(COUNTA(H6:H10)=0,"",COUNTIF(H6:H10,"Ya")/5*100) | I5: =IF(COUNTA(I6:I10)=0,"",COUNTIF(I6:I10,"Ya")/5*100) | J5: =IF(COUNTA(J6:J10)=0,"",COUNTIF(J6:J10,"Ya")/5*100) | K5: =IF(COUNTA(K6:K10)=0,"",COUNTIF(K6:K10,"Ya")/5*100) | L5: =IF(COUNTA(L6:L10)=0,"",COUNTIF(L6:L10,"Ya")/5*100) | ... Y5: =IF(COUNTA(Y6:Y10)=0,"",COUNTIF(Y6:Y10,"Ya")/5*100) | Z5: =_xlfn.IFERROR(AVERAGE(E5:Y5),"")
B6: D1a | C6: SIBISA digunakan untuk minimal satu jenis layanan adminduk
B7: D1b | C7: SIBISA digunakan untuk lebih dari satu jenis layanan, misalnya KTP-el dan KK
B8: D1c | C8: SIBISA digunakan untuk seluruh 4 jenis layanan: KTP-el, KK, Akta Kelahiran, dan KIA
B9: D1d | C9: Penggunaan SIBISA untuk seluruh layanan tersebut konsisten dalam 3 bulan terakhir, bukan uji coba sesaat
B10: D1e | C10: Tersedia data statistik penggunaan SIBISA per jenis layanan yang menunjukkan pemanfaatan aktif dan menyeluruh
B11: D2 | C11: Tersedia kanal digital resmi (website, medsos, WA Official) yang AKTIF untuk notifikasi jadwal jemput bola, status permohonan, dan info layanan | D11: 10 | E11: =IF(COUNTA(E12:E16)=0,"",COUNTIF(E12:E16,"Ya")/5*100) | F11: =IF(COUNTA(F12:F16)=0,"",COUNTIF(F12:F16,"Ya")/5*100) | G11: =IF(COUNTA(G12:G16)=0,"",COUNTIF(G12:G16,"Ya")/5*100) | H11: =IF(COUNTA(H12:H16)=0,"",COUNTIF(H12:H16,"Ya")/5*100) | I11: =IF(COUNTA(I12:I16)=0,"",COUNTIF(I12:I16,"Ya")/5*100) | J11: =IF(COUNTA(J12:J16)=0,"",COUNTIF(J12:J16,"Ya")/5*100) | K11: =IF(COUNTA(K12:K16)=0,"",COUNTIF(K12:K16,"Ya")/5*100) | L11: =IF(COUNTA(L12:L16)=0,"",COUNTIF(L12:L16,"Ya")/5*100) | ... Y11: =IF(COUNTA(Y12:Y16)=0,"",COUNTIF(Y12:Y16,"Ya")/5*100) | Z11: =_xlfn.IFERROR(AVERAGE(E11:Y11),"")
B12: D2a | C12: Kecamatan memiliki minimal satu kanal digital resmi (website/medsos/WA Official)
B13: D2b | C13: Kanal tersebut digunakan untuk menyampaikan notifikasi jadwal jemput bola
B14: D2c | C14: Kanal tersebut juga digunakan untuk info status permohonan dokumen
B15: D2d | C15: Kanal aktif memposting/merespons dalam 1 bulan terakhir, bukan kanal mati
B16: D2e | C16: Warga terkonfirmasi memanfaatkan kanal tersebut untuk memperoleh informasi, via wawancara/data interaksi
B17: D3 | C17: Integrasi data kependudukan dengan RS/klinik/puskesmas di wilayah kecamatan telah BERJALAN: warga dapat urus dokumen bersamaan kunjungan layanan kesehatan | D17: 10 | E17: =IF(COUNTA(E18:E22)=0,"",COUNTIF(E18:E22,"Ya")/5*100) | F17: =IF(COUNTA(F18:F22)=0,"",COUNTIF(F18:F22,"Ya")/5*100) | G17: =IF(COUNTA(G18:G22)=0,"",COUNTIF(G18:G22,"Ya")/5*100) | H17: =IF(COUNTA(H18:H22)=0,"",COUNTIF(H18:H22,"Ya")/5*100) | I17: =IF(COUNTA(I18:I22)=0,"",COUNTIF(I18:I22,"Ya")/5*100) | J17: =IF(COUNTA(J18:J22)=0,"",COUNTIF(J18:J22,"Ya")/5*100) | K17: =IF(COUNTA(K18:K22)=0,"",COUNTIF(K18:K22,"Ya")/5*100) | L17: =IF(COUNTA(L18:L22)=0,"",COUNTIF(L18:L22,"Ya")/5*100) | ... Y17: =IF(COUNTA(Y18:Y22)=0,"",COUNTIF(Y18:Y22,"Ya")/5*100) | Z17: =_xlfn.IFERROR(AVERAGE(E17:Y17),"")
B18: D3a | C18: Kerja sama/integrasi teknis dengan minimal satu RS/klinik/puskesmas telah disepakati
B19: D3b | C19: Sistem integrasi tersebut telah diuji dan berfungsi secara teknis
B20: D3c | C20: Warga benar-benar dapat mengurus dokumen kependudukan bersamaan kunjungan layanan kesehatan
B21: D3d | C21: Integrasi mencakup lebih dari satu fasilitas kesehatan di wilayah kecamatan
B22: D3e | C22: Tersedia data jumlah warga yang terlayani melalui skema integrasi ini secara berkala
B23: D4 | C23: Integrasi data kependudukan dengan sekolah & panti asuhan di wilayah kecamatan telah berjalan dan terdata sistematis dalam sistem terverifikasi | D23: 10 | E23: =IF(COUNTA(E24:E28)=0,"",COUNTIF(E24:E28,"Ya")/5*100) | F23: =IF(COUNTA(F24:F28)=0,"",COUNTIF(F24:F28,"Ya")/5*100) | G23: =IF(COUNTA(G24:G28)=0,"",COUNTIF(G24:G28,"Ya")/5*100) | H23: =IF(COUNTA(H24:H28)=0,"",COUNTIF(H24:H28,"Ya")/5*100) | I23: =IF(COUNTA(I24:I28)=0,"",COUNTIF(I24:I28,"Ya")/5*100) | J23: =IF(COUNTA(J24:J28)=0,"",COUNTIF(J24:J28,"Ya")/5*100) | K23: =IF(COUNTA(K24:K28)=0,"",COUNTIF(K24:K28,"Ya")/5*100) | L23: =IF(COUNTA(L24:L28)=0,"",COUNTIF(L24:L28,"Ya")/5*100) | ... Y23: =IF(COUNTA(Y24:Y28)=0,"",COUNTIF(Y24:Y28,"Ya")/5*100) | Z23: =_xlfn.IFERROR(AVERAGE(E23:Y23),"")
B24: D4a | C24: Kerja sama integrasi dengan minimal satu sekolah/panti asuhan telah disepakati
B25: D4b | C25: Sistem integrasi tersebut telah diuji dan berfungsi secara teknis
B26: D4c | C26: Data yang terintegrasi tersimpan dalam sistem yang terverifikasi, bukan pencatatan manual lepas
B27: D4d | C27: Integrasi mencakup lebih dari satu sekolah/panti asuhan di wilayah kecamatan
B28: D4e | C28: Tersedia laporan pemanfaatan integrasi ini yang diperbarui secara berkala
